<?xml version="1.0" ?>
<robot name="Dummy-URDF"
       xmlns:xacro="http://www.ros.org/wiki/xacro">

       <xacro:include filename="$(find Dummy-URDF_description)/urdf/materials.xacro" />
       <xacro:include filename="$(find Dummy-URDF_description)/urdf/Dummy-URDF.trans" />
       <xacro:include filename="$(find Dummy-URDF_description)/urdf/Dummy-URDF.gazebo" />
       <link name="base_link">
              <inertial>
                     <origin rpy="0 0 0" xyz="-1.231020991102519e-09 0.0021675762162932048 0.03625310876047439"/>
                     <mass value="2.993190613370791"/>
                     <inertia ixx="0.004786" ixy="-0.0" ixz="0.0" iyy="0.005416" iyz="-3.7e-05" izz="0.005881"/>
              </inertial>
              <visual>
                     <origin rpy="0 0 0" xyz="0 0 0"/>
                     <geometry>
                            <mesh filename="package://base_link.stl" scale="0.001 0.001 0.001"/>
                     </geometry>
                     <material name="light_grey">
                            <color rgba="0.66 0.66 0.66 1.000"/>
                     </material>
              </visual>
              <collision>
                     <origin rpy="0 0 0" xyz="0 0 0"/>
                     <geometry>
                            <mesh filename="package://base_link.stl" scale="0.001 0.001 0.001"/>
                     </geometry>
              </collision>
       </link>

       <link name="Joint1_1">
              <inertial>
                     <origin rpy="0 0 0" xyz="-0.005615648333236545 0.005656469769622364 0.012036816891445257"/>
                     <mass value="0.4092761251765545"/>
                     <inertia ixx="0.000177" ixy="5.6e-05" ixz="2.6e-05" iyy="0.000152" iyz="-4e-05" izz="0.000251"/>
              </inertial>
              <visual>
                     <origin rpy="0 0 0" xyz="-0.0 0.0 -0.0815"/>
                     <geometry>
                            <mesh filename="package://Joint1_1.stl" scale="0.001 0.001 0.001"/>
                     </geometry>
                     <material name="red">
                            <color rgba="0.9 0.0 0 1.000"/>
                     </material>
              </visual>
              <collision>
                     <origin rpy="0 0 0" xyz="-0.0 0.0 -0.0815"/>
                     <geometry>
                            <mesh filename="package://Joint1_1.stl" scale="0.001 0.001 0.001"/>
                     </geometry>
              </collision>
       </link>

       <link name="Joint2_and_Joint3_1">
              <inertial>
                     <origin rpy="0 0 0" xyz="0.02516708684327589 0.001868260257531111 0.06932558477120558"/>
                     <mass value="1.1904397439277807"/>
                     <inertia ixx="0.00435" ixy="-1.3e-05" ixz="0.000628" iyy="0.004611" iyz="1.4e-05" izz="0.000771"/>
              </inertial>
              <visual>
                     <origin rpy="0 0 0" xyz="0.0185 -0.035 -0.11"/>
                     <geometry>
                            <mesh filename="package://Joint2_and_Joint3_1.stl" scale="0.001 0.001 0.001"/>
                     </geometry>
                     <material name="red">
                            <color rgba="0.9 0.0 0 1.000"/>
                     </material>
              </visual>
              <collision>
                     <origin rpy="0 0 0" xyz="0.0185 -0.035 -0.11"/>
                     <geometry>
                            <mesh filename="package://Joint2_and_Joint3_1.stl" scale="0.001 0.001 0.001"/>
                     </geometry>
              </collision>
       </link>

       <link name="Joint4_1">
              <inertial>
                     <origin rpy="0 0 0" xyz="-0.013285345740308582 -0.02424483702989803 0.03565704153166732"/>
                     <mass value="0.3581657895432131"/>
                     <inertia ixx="0.000211" ixy="-2.4e-05" ixz="5.1e-05" iyy="0.000235" iyz="5.6e-05" izz="0.000134"/>
              </inertial>
              <visual>
                     <origin rpy="0 0 0" xyz="-0.01965 -0.035 -0.256"/>
                     <geometry>
                            <mesh filename="package://Joint4_1.stl" scale="0.001 0.001 0.001"/>
                     </geometry>
                     <material name="grey">
                            <color rgba="0.12 0.12 0.12 1.000"/>
                     </material>
              </visual>
              <collision>
                     <origin rpy="0 0 0" xyz="-0.01965 -0.035 -0.256"/>
                     <geometry>
                            <mesh filename="package://Joint4_1.stl" scale="0.001 0.001 0.001"/>
                     </geometry>
              </collision>
       </link>

       <link name="Joint5_1">
              <inertial>
                     <origin rpy="0 0 0" xyz="-0.011799159934342001 0.06777788508296304 0.0003449877805096757"/>
                     <mass value="0.3431533382899644"/>
                     <inertia ixx="0.000655" ixy="1.5e-05" ixz="1e-06" iyy="5.9e-05" iyz="0.0" izz="0.000665"/>
              </inertial>
              <visual>
                     <origin rpy="0 0 0" xyz="-0.0 -0.025 -0.307"/>
                     <geometry>
                            <mesh filename="package://Joint5_1.stl" scale="0.001 0.001 0.001"/>
                     </geometry>
                     <material name="red">
                            <color rgba="0.9 0.0 0 1.000"/>
                     </material>
              </visual>
              <collision>
                     <origin rpy="0 0 0" xyz="-0.0 -0.025 -0.307"/>
                     <geometry>
                            <mesh filename="package://Joint5_1.stl" scale="0.001 0.001 0.001"/>
                     </geometry>
              </collision>
       </link>

       <link name="Joint6_1">
              <inertial>
                     <origin rpy="0 0 0" xyz="-0.00014876263865433274 0.03810103090961503 1.2963027310741726e-05"/>
                     <mass value="0.11465179165554164"/>
                     <inertia ixx="9.3e-05" ixy="1.6e-05" ixz="-0.0" iyy="1.2e-05" iyz="0.0" izz="9.6e-05"/>
              </inertial>
              <visual>
                     <origin rpy="0 0 0" xyz="-0.0088 -0.15 -0.307"/>
                     <geometry>
                            <mesh filename="package://Joint6_1.stl" scale="0.001 0.001 0.001"/>
                     </geometry>
                     <material name="grey">
                            <color rgba="0.12 0.12 0.12 1.000"/>
                     </material>
              </visual>
              <collision>
                     <origin rpy="0 0 0" xyz="-0.0088 -0.15 -0.307"/>
                     <geometry>
                            <mesh filename="package://Joint6_1.stl" scale="0.001 0.001 0.001"/>
                     </geometry>
              </collision>
       </link>

       <link name="end_1">
              <inertial>
                     <origin rpy="0 0 0" xyz="-2.6054234055251144e-13 -0.006500000000000172 -1.5199126401910235e-09"/>
                     <mass value="0.008014988257471111"/>
                     <inertia ixx="0.0" ixy="0.0" ixz="-0.0" iyy="0.0" iyz="0.0" izz="0.0"/>
              </inertial>
              <visual>
                     <origin rpy="0 0 0" xyz="-0.0 -0.232 -0.307"/>
                     <geometry>
                            <mesh filename="package://end_1.stl" scale="0.001 0.001 0.001"/>
                     </geometry>
                     <material name="silver">
                            <color rgba="0.700 0.700 0.700 1.000"/>
                     </material>
              </visual>
              <collision>
                     <origin rpy="0 0 0" xyz="-0.0 -0.232 -0.307"/>
                     <geometry>
                            <mesh filename="package://end_1.stl" scale="0.001 0.001 0.001"/>
                     </geometry>
              </collision>
       </link>

       <joint name="Rev11" type="revolute">
              <origin rpy="0 0 0" xyz="0.0 0.0 0.0815"/>
              <parent link="base_link"/>
              <child link="Joint1_1"/>
              <axis xyz="0.0 -0.0 1.0"/>
              <limit effort="28.0" lower="-6.28318530718" upper="6.28318530718" velocity="3.2" />
              <dynamics damping="0.0" friction="0.0" />
       </joint>

       <joint name="Rev12" type="revolute">
              <origin rpy="0 0 0" xyz="-0.0185 0.035 0.0285"/>
              <parent link="Joint1_1"/>
              <child link="Joint2_and_Joint3_1"/>
              <axis xyz="-1.0 -0.0 0.0"/>
              <limit effort="28.0" lower="-6.28318530718" upper="6.28318530718" velocity="3.2" />
              <dynamics damping="0.0" friction="0.0" />
       </joint>

       <joint name="Rev13" type="revolute">
              <origin rpy="1.5707963 0 0" xyz="0.03815 0.0 0.146"/>
              <parent link="Joint2_and_Joint3_1"/>
              <child link="Joint4_1"/>
              <axis xyz="-1.0 -0.0 -0.0"/>
              <limit effort="28.0" lower="-6.28318530718" upper="6.28318530718" velocity="3.2" />
              <dynamics damping="0.0" friction="0.0" />
       </joint>

       <joint name="Rev14" type="revolute">
              <origin rpy="0 0 0" xyz="-0.01965 -0.01 0.051"/>
              <parent link="Joint4_1"/>
              <child link="Joint5_1"/>
              <axis xyz="-0.0 1.0 0.0"/>
              <limit effort="28.0" lower="-6.28318530718" upper="6.28318530718" velocity="3.2" />
              <dynamics damping="0.0" friction="0.0" />
       </joint>

       <joint name="Rev15" type="revolute">
              <origin rpy="0 0 0" xyz="0.0088 0.125 0.0"/>
              <parent link="Joint5_1"/>
              <child link="Joint6_1"/>
              <axis xyz="-1.0 -0.0 0.0"/>
              <limit effort="28.0" lower="-6.28318530718" upper="6.28318530718" velocity="3.2" />
              <dynamics damping="0.0" friction="0.0" />
       </joint>

       <joint name="Rev16" type="revolute">
              <origin rpy="0 0 0" xyz="-0.0088 0.082 0.0"/>
              <parent link="Joint6_1"/>
              <child link="end_1"/>
              <axis xyz="0.0 -1.0 -0.0"/>
              <limit effort="28.0" lower="-6.28318530718" upper="6.28318530718" velocity="3.2" />
              <dynamics damping="0.0" friction="0.0" />
       </joint>


       <chain_pair name="pair0">
              <base name="Rev11"/>
              <end name="Rev16"/>
       </chain_pair>
</robot>