<?xml version="1.0" encoding="utf-8"?>
<!-- This URDF was automatically created by SolidWorks to URDF Exporter! Originally created by Stephen Brawner (brawner@gmail.com) 
     Commit Version: 1.6.0-1-g15f4949  Build Version: 1.6.7594.29634
     For more information, please see http://wiki.ros.org/sw_urdf_exporter -->
<robot
  name="AG-ARM">
  <link
    name="base_link">
    <inertial>
      <origin
        xyz="1.0152E-11 0.040357 2.4248E-06"
        rpy="0 0 0" />
      <mass
        value="1.4779" />
      <inertia
        ixx="0.0070853"
        ixy="5.3113E-13"
        ixz="2.2969E-13"
        iyy="0.011853"
        iyz="-5.3973E-08"
        izz="0.0070854" />
    </inertial>
    <visual>
      <origin
        xyz="0 0 0"
        rpy="0 0 0" />
      <geometry>
        <mesh
          filename="package://AG-ARM/base_link.STL" />
      </geometry>
      <material
        name="">
        <color
          rgba="0.79216 0.81961 0.93333 1" />
      </material>
    </visual>
    <collision>
      <origin
        xyz="0 0 0"
        rpy="0 0 0" />
      <geometry>
        <mesh
          filename="package://AG-ARM/base_link.STL" />
      </geometry>
    </collision>
  </link>
  <link
    name="Link1">
    <inertial>
      <origin
        xyz="-0.032947 0.024006 -0.0067532"
        rpy="0 0 0" />
      <mass
        value="1.7773" />
      <inertia
        ixx="0.0034771"
        ixy="8.402E-05"
        ixz="4.0453E-07"
        iyy="0.00423"
        iyz="9.2255E-05"
        izz="0.0028706" />
    </inertial>
    <visual>
      <origin
        xyz="0 0 0"
        rpy="0 0 0" />
      <geometry>
        <mesh
          filename="package://AG-ARM/Link1.STL" />
      </geometry>
      <material
        name="">
        <color
          rgba="0.79216 0.81961 0.93333 1" />
      </material>
    </visual>
    <collision>
      <origin
        xyz="0 0 0"
        rpy="0 0 0" />
      <geometry>
        <mesh
          filename="package://AG-ARM/Link1.STL" />
      </geometry>
    </collision>
  </link>
  <joint
    name="Joint1"
    type="revolute">
    <origin
      xyz="0 0 0.1065"
      rpy="1.5708 0 3.141592654" />
    <parent
      link="base_link" />
    <child
      link="Link1" />
    <axis
      xyz="0 -1 0" />
    <limit
      lower="-3.1416"
      upper="3.1416"
      effort="0"
      velocity="0" />
  </joint>
  <link
    name="Link2">
    <inertial>
      <origin
        xyz="-0.018808 -2.3305E-05 -0.24154"
        rpy="0 0 0" />
      <mass
        value="0.8748" />
      <inertia
        ixx="0.0011927"
        ixy="-6.185E-08"
        ixz="4.1559E-05"
        iyy="0.0013702"
        iyz="2.6761E-07"
        izz="0.00070077" />
    </inertial>
    <visual>
      <origin
        xyz="0 0 0"
        rpy="0 0 0" />
      <geometry>
        <mesh
          filename="package://AG-ARM/Link2.STL" />
      </geometry>
      <material
        name="">
        <color
          rgba="0.79216 0.81961 0.93333 1" />
      </material>
    </visual>
    <collision>
      <origin
        xyz="0 0 0"
        rpy="0 0 0" />
      <geometry>
        <mesh
          filename="package://AG-ARM/Link2.STL" />
      </geometry>
    </collision>
  </link>
  <joint
    name="Joint2"
    type="revolute">
    <origin
      xyz="-0.075 0.0485 -0.122"
      rpy="1.5708 -1.5708 0" />
    <parent
      link="Link1" />
    <child
      link="Link2" />
    <axis
      xyz="1 0 0" />
    <limit
      lower="-3.1416"
      upper="3.1416"
      effort="0"
      velocity="0" />
  </joint>
  <link
    name="Link3">
    <inertial>
      <origin
        xyz="0.039428 1.3417E-05 0.0002002"
        rpy="0 0 0" />
      <mass
        value="0.23594" />
      <inertia
        ixx="0.00016941"
        ixy="-6.9616E-08"
        ixz="2.26E-05"
        iyy="0.00017893"
        iyz="6.2607E-08"
        izz="0.00011107" />
    </inertial>
    <visual>
      <origin
        xyz="0 0 0"
        rpy="0 0 0" />
      <geometry>
        <mesh
          filename="package://AG-ARM/Link3.STL" />
      </geometry>
      <material
        name="">
        <color
          rgba="0.79216 0.81961 0.93333 1" />
      </material>
    </visual>
    <collision>
      <origin
        xyz="0 0 0"
        rpy="0 0 0" />
      <geometry>
        <mesh
          filename="package://AG-ARM/Link3.STL" />
      </geometry>
    </collision>
  </link>
  <joint
    name="Joint3"
    type="revolute">
    <origin
      xyz="0.0715 0 -0.299"
      rpy="1.5708 0 0" />
    <parent
      link="Link2" />
    <child
      link="Link3" />
    <axis
      xyz="-1 0 0" />
    <limit
      lower="-3.1415926"
      upper="3.1415926"
      effort="0"
      velocity="0" />
  </joint>
  <link
    name="Link4">
    <inertial>
      <origin
        xyz="-0.0036544 -0.10244 -4.2839E-05"
        rpy="0 0 0" />
      <mass
        value="0.20981" />
      <inertia
        ixx="0.00013457"
        ixy="3.7665E-06"
        ixz="-1.0845E-07"
        iyy="8.7701E-05"
        iyz="3.7078E-07"
        izz="0.00015348" />
    </inertial>
    <visual>
      <origin
        xyz="0 0 0"
        rpy="0 0 0" />
      <geometry>
        <mesh
          filename="package://AG-ARM/Link4.STL" />
      </geometry>
      <material
        name="">
        <color
          rgba="0.79216 0.81961 0.93333 1" />
      </material>
    </visual>
    <collision>
      <origin
        xyz="0 0 0"
        rpy="0 0 0" />
      <geometry>
        <mesh
          filename="package://AG-ARM/Link4.STL" />
      </geometry>
    </collision>
  </link>
  <joint
    name="Joint4"
    type="revolute">
    <origin
      xyz="0.0505 0 -0.051"
      rpy="1.5708 0 0" />
    <parent
      link="Link3" />
    <child
      link="Link4" />
    <axis
      xyz="0 1 0" />
    <limit
      lower="-3.1415926"
      upper="3.1415926"
      effort="0"
      velocity="0" />
  </joint>
  <link
    name="Link5">
    <inertial>
      <origin
        xyz="2.9363E-07 0.027533 0.073361"
        rpy="0 0 0" />
      <mass
        value="0.14057" />
      <inertia
        ixx="0.00013835"
        ixy="-3.9823E-11"
        ixz="-1.7895E-09"
        iyy="0.00013428"
        iyz="-2.0279E-05"
        izz="4.9732E-05" />
    </inertial>
    <visual>
      <origin
        xyz="0 0 0"
        rpy="0 0 0" />
      <geometry>
        <mesh
          filename="package://AG-ARM/Link5.STL" />
      </geometry>
      <material
        name="">
        <color
          rgba="0.79216 0.81961 0.93333 1" />
      </material>
    </visual>
    <collision>
      <origin
        xyz="0 0 0"
        rpy="0 0 0" />
      <geometry>
        <mesh
          filename="package://AG-ARM/Link5.STL" />
      </geometry>
    </collision>
  </link>
  <joint
    name="Joint5"
    type="revolute">
    <origin
      xyz="0.045 -0.142 0"
      rpy="1.5708 -1.5708 0" />
    <parent
      link="Link4" />
    <child
      link="Link5" />
    <axis
      xyz="0 1 0" />
    <limit
      lower="-3.1415926"
      upper="3.1415926"
      effort="0"
      velocity="0" />
  </joint>
  <link
    name="Link6">
    <inertial>
      <origin
        xyz="-1.6898E-10 -5.5511E-17 0.0085"
        rpy="0 0 0" />
      <mass
        value="0.0014137" />
      <inertia
        ixx="6.8506E-08"
        ixy="-4.6676E-26"
        ixz="-2.2143E-17"
        iyy="6.8506E-08"
        iyz="5.3848E-23"
        izz="2.6507E-08" />
    </inertial>
    <visual>
      <origin
        xyz="0 0 0"
        rpy="0 0 0" />
      <geometry>
        <mesh
          filename="package://AG-ARM/Link6.STL" />
      </geometry>
      <material
        name="">
        <color
          rgba="0.79216 0.81961 0.93333 1" />
      </material>
    </visual>
    <collision>
      <origin
        xyz="0 0 0"
        rpy="0 0 0" />
      <geometry>
        <mesh
          filename="package://AG-ARM/Link6.STL" />
      </geometry>
    </collision>
  </link>
  <joint
    name="Joint6"
    type="revolute">
    <origin
      xyz="0 0.045 0.136"
      rpy="3.1416 0 -1.5708" />
    <parent
      link="Link5" />
    <child
      link="Link6" />
    <axis
      xyz="0 0 1" />
    <limit
      lower="-3.1415926"
      upper="3.1415926"
      effort="0"
      velocity="0" />
  </joint>
</robot>